`try...catch` 用于捕获同步执行代码块中的异常，当涉及到异步代码如 `setTimeout` 中的错误时，`try...catch` 无法直接捕获这些异常。这是因为 `setTimeout` 中的代码是在函数执行栈之外的未来某个时间点异步执行的，而 `try...catch` 只能捕获其直接执行上下文中的错误

当 `setTimeout` 被调用时，其回调函数被加入到事件队列中，待清空当前执行栈后再执行。由于 `try...catch` 是在当前执行栈中捕获错误，一旦当前执行栈执行完成，`try...catch` 就失去了作用范围，因此无法捕获 `setTimeout` 回调中发生的错误

```JavaScript
try {
  setTimeout(() => {
    throw new Error("Error in setTimeout");
  }, 1000);
} catch (err) {
  console.log("Caught an error!", err);
}
```

在这个示例中，`setTimeout` 中的错误不会被 `try...catch` 捕获，错误信息不会被打印

为捕获 `setTimeout` 中的错误，你可以在 `setTimeout` 的回调函数内部使用 `try...catch`：

```JavaScript
setTimeout(() => {
  try {
    throw new Error("Error in setTimeout");
  } catch (err) {
    console.log("Caught an error!", err);
  }
}, 1000);
```

在这种情况下，`try...catch` 位于 `setTimeout` 的回调函数内部，因此可以捕获并处理回调函数中发生的错误